Workbook

Sheet Pošte
A1: ID | B1: Code | C1: Name | D1: Regija | E1: Regija.id | F1: Je pošta občina? | G1: Občina.id | H1: Regija.občine | I1: Napačna regija?
A2: 190 | B2: 1000 | C2: Ljubljana | D2: Osrednjeslovenska | E2: =_xlfn.XLOOKUP(D2,Regije!B:B,Regije!A:A) -> 8 | F2: =_xlfn.IFNA(_xlfn.XLOOKUP(C2,'regije_občine 212'!$D$4:$D$215,'regije_občine 212'!$D$4:$D$215)=C2,FALSE) -> TRUE | H2: =_xlfn.IFNA(_xlfn.XLOOKUP(C2,'regije_občine 212'!$D$4:$D$215,'regije_občine 212'!$B$4:$B$215),"") -> Osrednjeslovenska | I2: =IF(AND(H2<>"",H2<>D2),"drugačna regija!","")
A3: 191 | B3: 1001 | C3: Ljubljana - poštni predali | D3: Osrednjeslovenska | E3: =_xlfn.XLOOKUP(D3,Regije!B:B,Regije!A:A) -> 8 | F3: =_xlfn.IFNA(_xlfn.XLOOKUP(C3,'regije_občine 212'!$D$4:$D$215,'regije_občine 212'!$D$4:$D$215)=C3,FALSE) -> FALSE | H3: =_xlfn.IFNA(_xlfn.XLOOKUP(C3,'regije_občine 212'!$D$4:$D$215,'regije_občine 212'!$B$4:$B$215),"") | I3: =IF(AND(H3<>"",H3<>D3),"drugačna regija!","")
A4: 195 | B4: 1002 | C4: Ljubljana - poštni center | D4: Osrednjeslovenska | E4: =_xlfn.XLOOKUP(D4,Regije!B:B,Regije!A:A) -> 8 | F4: =_xlfn.IFNA(_xlfn.XLOOKUP(C4,'regije_občine 212'!$D$4:$D$215,'regije_občine 212'!$D$4:$D$215)=C4,FALSE) -> FALSE | H4: =_xlfn.IFNA(_xlfn.XLOOKUP(C4,'regije_občine 212'!$D$4:$D$215,'regije_občine 212'!$B$4:$B$215),"") | I4: =IF(AND(H4<>"",H4<>D4),"drugačna regija!","")
A5: 196 | B5: 1210 | C5: Ljubljana - Šentvid | D5: Osrednjeslovenska | E5: =_xlfn.XLOOKUP(D5,Regije!B:B,Regije!A:A) -> 8 | F5: =_xlfn.IFNA(_xlfn.XLOOKUP(C5,'regije_občine 212'!$D$4:$D$215,'regije_občine 212'!$D$4:$D$215)=C5,FALSE) -> FALSE | H5: =_xlfn.IFNA(_xlfn.XLOOKUP(C5,'regije_občine 212'!$D$4:$D$215,'regije_občine 212'!$B$4:$B$215),"") | I5: =IF(AND(H5<>"",H5<>D5),"drugačna regija!","")
A6: 197 | B6: 1211 | C6: Ljubljana - Šmartno | D6: Osrednjeslovenska | E6: =_xlfn.XLOOKUP(D6,Regije!B:B,Regije!A:A) -> 8 | F6: =_xlfn.IFNA(_xlfn.XLOOKUP(C6,'regije_občine 212'!$D$4:$D$215,'regije_občine 212'!$D$4:$D$215)=C6,FALSE) -> FALSE | H6: =_xlfn.IFNA(_xlfn.XLOOKUP(C6,'regije_občine 212'!$D$4:$D$215,'regije_občine 212'!$B$4:$B$215),"") | I6: =IF(AND(H6<>"",H6<>D6),"drugačna regija!","")
A7: 225 | B7: 1215 | C7: Medvode | D7: Osrednjeslovenska | E7: =_xlfn.XLOOKUP(D7,Regije!B:B,Regije!A:A) -> 8 | F7: =_xlfn.IFNA(_xlfn.XLOOKUP(C7,'regije_občine 212'!$D$4:$D$215,'regije_občine 212'!$D$4:$D$215)=C7,FALSE) -> TRUE | H7: =_xlfn.IFNA(_xlfn.XLOOKUP(C7,'regije_občine 212'!$D$4:$D$215,'regije_občine 212'!$B$4:$B$215),"") -> Osrednjeslovenska | I7: =IF(AND(H7<>"",H7<>D7),"drugačna regija!","")
A8: 349 | B8: 1216 | C8: Smlednik | D8: Osrednjeslovenska | E8: =_xlfn.XLOOKUP(D8,Regije!B:B,Regije!A:A) -> 8 | F8: =_xlfn.IFNA(_xlfn.XLOOKUP(C8,'regije_občine 212'!$D$4:$D$215,'regije_občine 212'!$D$4:$D$215)=C8,FALSE) -> FALSE | H8: =_xlfn.IFNA(_xlfn.XLOOKUP(C8,'regije_občine 212'!$D$4:$D$215,'regije_občine 212'!$B$4:$B$215),"") | I8: =IF(AND(H8<>"",H8<>D8),"drugačna regija!","")
A9: 447 | B9: 1217 | C9: Vodice | D9: Osrednjeslovenska | E9: =_xlfn.XLOOKUP(D9,Regije!B:B,Regije!A:A) -> 8 | F9: =_xlfn.IFNA(_xlfn.XLOOKUP(C9,'regije_občine 212'!$D$4:$D$215,'regije_občine 212'!$D$4:$D$215)=C9,FALSE) -> TRUE | H9: =_xlfn.IFNA(_xlfn.XLOOKUP(C9,'regije_občine 212'!$D$4:$D$215,'regije_občine 212'!$B$4:$B$215),"") -> Osrednjeslovenska | I9: =IF(AND(H9<>"",H9<>D9),"drugačna regija!","")
A10: 154 | B10: 1218 | C10: Komenda | D10: Osrednjeslovenska | E10: =_xlfn.XLOOKUP(D10,Regije!B:B,Regije!A:A) -> 8 | F10: =_xlfn.IFNA(_xlfn.XLOOKUP(C10,'regije_občine 212'!$D$4:$D$215,'regije_občine 212'!$D$4:$D$215)=C10,FALSE) -> TRUE | H10: =_xlfn.IFNA(_xlfn.XLOOKUP(C10,'regije_občine 212'!$D$4:$D$215,'regije_občine 212'!$B$4:$B$215),"") -> Osrednjeslovenska | I10: =IF(AND(H10<>"",H10<>D10),"drugačna regija!","")
A11: 180 | B11: 1219 | C11: Laze v Tuhinju | D11: Osrednjeslovenska | E11: =_xlfn.XLOOKUP(D11,Regije!B:B,Regije!A:A) -> 8 | F11: =_xlfn.IFNA(_xlfn.XLOOKUP(C11,'regije_občine 212'!$D$4:$D$215,'regije_občine 212'!$D$4:$D$215)=C11,FALSE) -> FALSE | H11: =_xlfn.IFNA(_xlfn.XLOOKUP(C11,'regije_občine 212'!$D$4:$D$215,'regije_občine 212'!$B$4:$B$215),"") | I11: =IF(AND(H11<>"",H11<>D11),"drugačna regija!","")
A12: 240 | B12: 1221 | C12: Motnik | D12: Osrednjeslovenska | E12: =_xlfn.XLOOKUP(D12,Regije!B:B,Regije!A:A) -> 8 | F12: =_xlfn.IFNA(_xlfn.XLOOKUP(C12,'regije_občine 212'!$D$4:$D$215,'regije_občine 212'!$D$4:$D$215)=C12,FALSE) -> FALSE | H12: =_xlfn.IFNA(_xlfn.XLOOKUP(C12,'regije_občine 212'!$D$4:$D$215,'regije_občine 212'!$B$4:$B$215),"") | I12: =IF(AND(H12<>"",H12<>D12),"drugačna regija!","")
A13: 423 | B13: 1222 | C13: Trojane | D13: Osrednjeslovenska | E13: =_xlfn.XLOOKUP(D13,Regije!B:B,Regije!A:A) -> 8 | F13: =_xlfn.IFNA(_xlfn.XLOOKUP(C13,'regije_občine 212'!$D$4:$D$215,'regije_občine 212'!$D$4:$D$215)=C13,FALSE) -> FALSE | H13: =_xlfn.IFNA(_xlfn.XLOOKUP(C13,'regije_občine 212'!$D$4:$D$215,'regije_občine 212'!$B$4:$B$215),"") | I13: =IF(AND(H13<>"",H13<>D13),"drugačna regija!","")
... A484: 479 | B484: 9999 | C484: (tujina) | D484: Tujina | E484: =_xlfn.XLOOKUP(D484,Regije!B:B,Regije!A:A) -> #N/A | F484: =_xlfn.IFNA(_xlfn.XLOOKUP(C484,'regije_občine 212'!$D$4:$D$215,'regije_občine 212'!$D$4:$D$215)=C484,FALSE) -> FALSE | H484: =_xlfn.IFNA(_xlfn.XLOOKUP(C484,'regije_občine 212'!$D$4:$D$215,'regije_občine 212'!$B$4:$B$215),"") | I484: =IF(AND(H484<>"",H484<>D484),"drugačna regija!","")

Sheet Regije
A1: ID | B1: Name | E1: x1 | F1: x2
A2: 9 | B2: Gorenjska | E2: Gorenjska | F2: 45
A3: 11 | B3: Goriška | E3: Goriška | F3: 43
A4: 7 | B4: Jugovzhodna Slovenija | E4: Jugovzhodna Slovenija | F4: 47
A5: 3 | B5: Koroška | E5: Koroška | F5: 19
A6: 12 | B6: Obalno-kraška | E6: Obalno-kraška | F6: 27
A7: 8 | B7: Osrednjeslovenska | E7: Osrednjeslovenska | F7: 61
A8: 2 | B8: Podravska | E8: Podravska | F8: 79
A9: 1 | B9: Pomurska | E9: Pomurska | F9: 37
A10: 6 | B10: Posavska | E10: Posavska | F10: 30
A11: 10 | B11: Primorsko-notranjska | E11: Primorsko-notranjska | F11: 17
A12: 4 | B12: Savinjska | E12: Savinjska | F12: 64
A13: 5 | B13: Zasavska | E13: Zasavska | F13: 9

Sheet regije_občine 212
A1: Statistične regije - NUTS 3 (12) / občine - SKTE 5 (212)
A3: Šifra statistične regije | B3: Ime statistične regije | C3: Šifra občine | D3: Ime občine
A4: 01 | B4: Pomurska | C4: 002 | D4: Beltinci
A5: 01 | B5: Pomurska | C5: 010 | D5: Tišina
A6: 01 | B6: Pomurska | C6: 015 | D6: Črenšovci
A7: 01 | B7: Pomurska | C7: 029 | D7: Gornja Radgona
A8: 01 | B8: Pomurska | C8: 031 | D8: Gornji Petrovci
A9: 01 | B9: Pomurska | C9: 033 | D9: Šalovci
A10: 01 | B10: Pomurska | C10: 047 | D10: Kobilje
A11: 01 | B11: Pomurska | C11: 056 | D11: Kuzma
A12: 01 | B12: Pomurska | C12: 059 | D12: Lendava/Lendva
A13: 01 | B13: Pomurska | C13: 063 | D13: Ljutomer
A14: 01 | B14: Pomurska | C14: 078 | D14: Moravske Toplice
... A17: 01 | B17: Pomurska | C17: 097 | D17: Puconci
A18: 01 | B18: Pomurska | C18: 100 | D18: Radenci
A19: 01 | B19: Pomurska | C19: 105 | D19: Rogašovci
A20: 01 | B20: Pomurska | C20: 116 | D20: Sveti Jurij ob Ščavnici
A21: 01 | B21: Pomurska | C21: 132 | D21: Turnišče
A22: 01 | B22: Pomurska | C22: 152 | D22: Cankova
A23: 01 | B23: Pomurska | C23: 156 | D23: Dobrovnik/Dobronak
A24: 01 | B24: Pomurska | C24: 158 | D24: Grad
A25: 01 | B25: Pomurska | C25: 161 | D25: Hodoš/Hodos
A26: 01 | B26: Pomurska | C26: 166 | D26: Križevci
A27: 01 | B27: Pomurska | C27: 176 | D27: Razkrižje
A28: 01 | B28: Pomurska | C28: 187 | D28: Velika Polana
A29: 01 | B29: Pomurska | C29: 188 | D29: Veržej
A30: 01 | B30: Pomurska | C30: 195 | D30: Apače
A31: 02 | B31: Podravska | C31: 018 | D31: Destrnik
A32: 02 | B32: Podravska | C32: 024 | D32: Dornava
A33: 02 | B33: Podravska | C33: 026 | D33: Duplek
A34: 02 | B34: Podravska | C34: 028 | D34: Gorišnica
A35: 02 | B35: Podravska | C35: 042 | D35: Juršinci
A36: 02 | B36: Podravska | C36: 045 | D36: Kidričevo
A37: 02 | B37: Podravska | C37: 055 | D37: Kungota
A38: 02 | B38: Podravska | C38: 058 | D38: Lenart
A39: 02 | B39: Podravska | C39: 069 | D39: Majšperk
A40: 02 | B40: Podravska | C40: 070 | D40: Maribor
A41: 02 | B41: Podravska | C41: 087 | D41: Ormož
A42: 02 | B42: Podravska | C42: 089 | D42: Pesnica
... A44: 02 | B44: Podravska | C44: 098 | D44: Rače - Fram
...
